<?xml version="1.0"?>
<robot name="chitty">
    <link name="base_link">
        <visual>
            <geometry>
                <cylinder radius="0.2" length="0.1"/>
            </geometry>
            <material name="blue">
                <color rgba="0 0 1 1"/>
        </visual>
        <collision>
            <geometry>
                <cylinder radius="0.2" length="0.1"/>
            </geometry>
        </collision>
    </link>
    <link name="left_wheel">
        <visual>
            <geometry>
                <cylinder radius="0.1" length="0.05"/>
            </geometry>
            <material name="red">
                <color rgba="1 0 0 1"/>
            </material>
        </visual>
        <collision>
            <geometry>
                <cylinder radius="0.1" length="0.05"/>
            </geometry>
        </collision>
    </link>
    <link name="right_wheel">
        <visual>
            <geometry>
                <cylinder radius="0.1" length="0.05"/>
            </geometry>
            <material name="green">
                <color rgba="0 1 0 1"/>
            </material>
        </visual>
        <collision>
            <geometry>
                <cylinder radius="0.1" length="0.05"/>
            </geometry>
        </collision>
    </link>
    <joint name="left_wheel_joint" type="continuous">
        <parent link="base_link"/>
        <child link="left_wheel"/>
        <origin xyz="0 -0.25 0" rpy="1.5707 0.0 0.0"/>
        <axis xyz="0 1 0"/>
    </joint>
    <joint name="right_wheel_joint" type="continuous">
        <parent link="base_link"/>
        <child link="right_wheel"/>
        <origin xyz="0 0.25 0" rpy="1.5707 0.0 0.0"/>
        <axis xyz="0 1 0"/>
    </joint>
</robot>